> try-catch

对于多数开发者来说，错误处理最自然的形式就是同步的try..catch结构。遗憾的是，它只能是同步的，无法用于异步代码模式

> error-firsr的回调风格

```
function foo(cb) {
  setTimeout( function() {
    try {
      var x = baz.bar();
      cb( null, x ); //成功
    } catch(err) {
      cb(err);
    }
  },100);
}

foo( function(err, val) {
    if(err) {
      error( err ) ;
    } else {
      log( val );
    }
})
```

严格来说，这一类错误处理是支持异步的，但完全无法很好的组合，多级error-firsr回调交织在一起，再加上无所不再的if检查语句，都不可避免地导致了回调地狱的风险

> Promise的分离回调风格

```
var p = Promise.reject( "Oops" );
p.then(
    function fulfilled() {
      //永远不会到达这里
    },
    function rejected(err) {
      error( err ); //"Oops"
    }
);
```

尽管表面看来，这种出错处理模式很合理，但彻底掌握 Promise 错误处理的各种细微差别 常常还是有些难度的。考虑下面这种情况

```
var p = Promise.resolve( 42 );
p.then(
    function fulfilled(msg) {
      // 数字没有string函数，所以会抛出错误
      log( msg.toLowerCase() );
    },
    function rejected(err) {
      // 永远不会到达这里
    }
);
```

如果 msg.toLowerCase() 合法地抛出一个错误(事实确实如此!)，为什么我们的错误处理 函数没有得到通知呢?正如前面解释过的，这是因为那个错误处理函数是为promise p准 备的，而这个 promise 已经用值 42 填充了。promise p 是不可变的，所以唯一可以被通知这 个错误的 promise 是从 p.then(..) 返回的那一个，但我们在此例中没有捕捉。

> 在最后以一个catch()结束

```
var p = Promise.resolve( 42 );
p.then(
    function fulfilled(msg){
// 数字没有string函数，所以会抛出错误
        console.log( msg.toLowerCase() );
    }
)
.catch( handleErrors );
```

如果 handleErrors(..) 本身内部也有错误怎么办呢?谁来捕捉它?还有一个没人处理的 promise:catch(..) 返回的那一个。我们没有捕获这个 promise 的结果，也没有为其注册 拒绝处理函数。
